Workbook

Sheet Inputs
B2: Project Inputs & Assumptions
B3: 899 Virginia Park St, Detroit MI 48202 — Claim 061004792 (Liberty Mutual) — DOL 02/26/2026 — Freezing / attic supply line
B4: Edit YELLOW cells only. All quantities and totals recalculate automatically.
B6: Parameter | C6: Value | D6: Unit | E6: Notes / Source
B7: Floor 1 area (SF) | C7: 940.7 | D7: SF | E7: Actual — Xactimate sketch '1st floor', claim 061004792
B8: Floor 2 area (SF) | C8: 956.28 | D8: SF | E8: Actual — sketch '2nd floor 2'
B9: Floor 3 / attic finished area (SF) | C9: 541.73 | D9: SF | E9: Actual — sketch '3rd floor 2'
B10: Average ceiling height (FT) | C10: 9 | D10: FT | E10: Historic homes often 9-10 ft on lower floors
B11: Wall+ceiling surface multiplier (x floor area) | C11: 4.56 | D11: x | E11: Actual: 11,112 SF walls+ceilings above grade / 2,439 SF floor (basement B1 2 adds 3,471 SF surface, excluded)
B12: Electrical openings per 100 SF floor | C12: 2.5 | D12: EA | E12: Outlets + switches + fixtures; NEC receptacle spacing will add openings vs. original
B13: Detroit location factor (RS Means CCI) | C13: 1.05 | D13: x | E13: User to validate against current RS Means City Cost Index for Detroit
B14: GC overhead & profit | C14: 0.18 | D14: % | E14: Typical 15-22% on insurance restoration work
B15: Contingency | C15: 0.1 | D15: % | E15: Hidden conditions: hazmat, framing rot, code items
B16: Wall finish system toggle (1 = drywall+skim, 2 = 3-coat plaster) | C16: 1 | D16: - | E16: Set to 2 if insurer owes like-kind lath & plaster
B18: Derived Quantities
B19: Total floor area (SF) | C19: =C7+C8+C9 -> 2438.71
B20: Total wall + ceiling surface (SF) | C20: =C19*C11 -> 11120.518
B21: Electrical openings (EA) | C21: =ROUND(C19/100*C12,0) -> 61
B23: Legend:
B24: Yellow / blue = edit these | Black = formula, do not edit | Green = pulls from another sheet

Sheet Estimate
B2: Restoration Estimate — Line Item Detail
B3: Unit costs are 2026 national-average ranges (installed, incl. labor+material) before location factor. Validate every line against RS Means and enter the Means unit cost in col K/L.
B5: CSI Div | C5: Item Description | D5: Unit | E5: Qty | F5: Unit $ Low | G5: Unit $ High | H5: Ext. $ Low | I5: Ext. $ High | J5: RS Means Line # | K5: Means Unit $ | L5: Means Ext. $ | M5: Variance vs Mid | N5: Notes
B6: MECHANICAL
B7: 23 52 | C7: Boiler combustion/safety inspection & service (ran dry — check sections, LWCO) | D7: LS | E7: 1 | F7: 350 | G7: 700 | H7: =E7*F7 -> 350 | I7: =E7*G7 -> 700 | L7: =IF(K7="","",E7*K7) | M7: =IF(K7="","",IF((F7+G7)/2=0,"",K7/((F7+G7)/2)-1)) | N7: If sections cracked from dry-firing, see replacement line
B8: 23 52 | C8: Boiler replacement contingency (cast-iron, hydronic, ~150-200 MBH) | D8: LS | E8: 1 | F8: 8000 | G8: 16000 | H8: =E8*F8 -> 8000 | I8: =E8*G8 -> 16000 | L8: =IF(K8="","",E8*K8) | M8: =IF(K8="","",IF((F8+G8)/2=0,"",K8/((F8+G8)/2)-1)) | N8: Carry as contingency until inspection report; delete line if boiler passes
B9: 23 82 | C9: Radiator system drain, refill, bleed, TRV/valve repacking allowance | D9: LS | E9: 1 | F9: 800 | G9: 2000 | H9: =E9*F9 -> 800 | I9: =E9*G9 -> 2000 | L9: =IF(K9="","",E9*K9) | M9: =IF(K9="","",IF((F9+G9)/2=0,"",K9/((F9+G9)/2)-1)) | N9: 3 floors of radiators disturbed by demo
B10: 22 11 | C10: Repair/replace burst domestic supply line at attic + isolation valves | D10: LS | E10: 1 | F10: 1500 | G10: 3500 | H10: =E10*F10 -> 1500 | I10: =E10*G10 -> 3500 | L10: =IF(K10="","",E10*K10) | M10: =IF(K10="","",IF((F10+G10)/2=0,"",K10/((F10+G10)/2)-1)) | N10: Cause of loss — insurer covers resulting damage; pipe itself may be excluded
B11: 22 07 | C11: Re-insulate attic domestic piping (freeze protection) | D11: LS | E11: 1 | F11: 500 | G11: 1500 | H11: =E11*F11 -> 500 | I11: =E11*G11 -> 1500 | L11: =IF(K11="","",E11*K11) | M11: =IF(K11="","",IF((F11+G11)/2=0,"",K11/((F11+G11)/2)-1)) | N11: Root-cause prevention; may be code/ordinance item
C12: MECHANICAL SUBTOTAL | H12: =SUM(H7:H11) -> 11150 | I12: =SUM(I7:I11) -> 23700 | L12: =SUM(L7:L11) -> 0
B14: ELECTRICAL
B15: 26 05 | C15: Full knob & tube rewire — copper NM, all branch circuits (walls open) | D15: SF | E15: =Inputs!$C$19 -> 2438.71 | F15: 8 | G15: 14 | H15: =E15*F15 -> 19509.68 | I15: =E15*G15 -> 34141.94 | L15: =IF(K15="","",E15*K15) | M15: =IF(K15="","",IF((F15+G15)/2=0,"",K15/((F15+G15)/2)-1)) | N15: Open-wall condition = low end of $10-20/SF market range
B16: 26 24 | C16: Service/panel upgrade to 200A + grounding electrode system | D16: LS | E16: 1 | F16: 2500 | G16: 4500 | H16: =E16*F16 -> 2500 | I16: =E16*G16 -> 4500 | L16: =IF(K16="","",E16*K16) | M16: =IF(K16="","",IF((F16+G16)/2=0,"",K16/((F16+G16)/2)-1)) | N16: K&T homes typically 60A service; likely required by code
B17: 26 27 | C17: Period-style wiring devices (push-button switches, plates) premium | D17: EA | E17: =Inputs!$C$21 -> 61 | F17: 25 | G17: 60 | H17: =E17*F17 -> 1525 | I17: =E17*G17 -> 3660 | L17: =IF(K17="","",E17*K17) | M17: =IF(K17="","",IF((F17+G17)/2=0,"",K17/((F17+G17)/2)-1)) | N17: Premium over builder-grade; historic character line item
B18: 26 05 | C18: AFCI/GFCI protection + smoke/CO interconnect (code-required) | D18: LS | E18: 1 | F18: 1200 | G18: 2500 | H18: =E18*F18 -> 1200 | I18: =E18*G18 -> 2500 | L18: =IF(K18="","",E18*K18) | M18: =IF(K18="","",IF((F18+G18)/2=0,"",K18/((F18+G18)/2)-1)) | N18: Ordinance & Law coverage candidate
B19: 26 05 | C19: Electrical permits & inspections (City of Detroit) | D19: LS | E19: 1 | F19: 300 | G19: 900 | H19: =E19*F19 -> 300 | I19: =E19*G19 -> 900 | L19: =IF(K19="","",E19*K19) | M19: =IF(K19="","",IF((F19+G19)/2=0,"",K19/((F19+G19)/2)-1))
C20: ELECTRICAL SUBTOTAL | H20: =SUM(H15:H19) -> 25034.68 | I20: =SUM(I15:I19) -> 45701.94 | L20: =SUM(L15:L19) -> 0
B22: STRUCTURAL
B23: 06 11 | C23: Attic framing/sheathing repair at burst location — allowance | D23: LS | E23: 1 | F23: 2000 | G23: 6000 | H23: =E23*F23 -> 2000 | I23: =E23*G23 -> 6000 | L23: =IF(K23="","",E23*K23) | M23: =IF(K23="","",IF((F23+G23)/2=0,"",K23/((F23+G23)/2)-1)) | N23: Scope TBD after demo exposes framing
B24: 06 11 | C24: Joist/subfloor sistering & repair allowance (saturated members) | D24: LS | E24: 1 | F24: 1500 | G24: 5000 | H24: =E24*F24 -> 1500 | I24: =E24*G24 -> 5000 | L24: =IF(K24="","",E24*K24) | M24: =IF(K24="","",IF((F24+G24)/2=0,"",K24/((F24+G24)/2)-1)) | N24: Water traveled 3 floors; probe after demo
B25: 02 87 | C25: Antimicrobial treatment / mold remediation of framing cavities | D25: SF | E25: =Inputs!$C$19 -> 2438.71 | F25: 1 | G25: 3 | H25: =E25*F25 -> 2438.71 | I25: =E25*G25 -> 7316.13 | L25: =IF(K25="","",E25*K25) | M25: =IF(K25="","",IF((F25+G25)/2=0,"",K25/((F25+G25)/2)-1)) | N25: Priced on affected floor area; adjust to actual affected SF
B26: 02 26 | C26: Asbestos survey (plaster, pipe insulation) + lead paint XRF | D26: LS | E26: 1 | F26: 500 | G26: 1200 | H26: =E26*F26 -> 500 | I26: =E26*G26 -> 1200 | L26: =IF(K26="","",E26*K26) | M26: =IF(K26="","",IF((F26+G26)/2=0,"",K26/((F26+G26)/2)-1)) | N26: Pre-1978 home — required before demo in most jurisdictions
C27: STRUCTURAL SUBTOTAL | H27: =SUM(H23:H26) -> 6438.71 | I27: =SUM(I23:I26) -> 19516.13 | L27: =SUM(L23:L26) -> 0
B29: ARCHITECTURAL
B30: 02 41 | C30: Demolition — plaster & lath walls/ceilings, bag & dispose | D30: SF | E30: =Inputs!$C$20 -> 11120.518 | F30: 2 | G30: 4 | H30: =E30*F30 -> 22241.035 | I30: =E30*G30 -> 44482.07 | L30: =IF(K30="","",E30*K30) | M30: =IF(K30="","",IF((F30+G30)/2=0,"",K30/((F30+G30)/2)-1)) | N30: Includes dumpsters; lead-safe practices below
B31: 02 83 | C31: Lead-safe containment premium (RRP): poly, neg. air, HEPA clean | D31: SF | E31: =Inputs!$C$20 -> 11120.518 | F31: 0.5 | G31: 1.5 | H31: =E31*F31 -> 5560.2588 | I31: =E31*G31 -> 16680.776 | L31: =IF(K31="","",E31*K31) | M31: =IF(K31="","",IF((F31+G31)/2=0,"",K31/((F31+G31)/2)-1)) | N31: EPA RRP compliance, pre-1978
B32: 07 21 | C32: Insulation — exterior wall cavities + attic (code upgrade) | D32: SF | E32: =Inputs!$C$19 -> 2438.71 | F32: 1.5 | G32: 3.5 | H32: =E32*F32 -> 3658.065 | I32: =E32*G32 -> 8535.485 | L32: =IF(K32="","",E32*K32) | M32: =IF(K32="","",IF((F32+G32)/2=0,"",K32/((F32+G32)/2)-1)) | N32: Ordinance & Law candidate; walls open = cheap to do now
B33: 09 29 | C33: Drywall 1/2" hang, tape, finish L4 — walls & ceilings | D33: SF | E33: =IF(Inputs!$C$16=1,Inputs!$C$20,0) -> 11120.518 | F33: 2.5 | G33: 4 | H33: =E33*F33 -> 27801.294 | I33: =E33*G33 -> 44482.07 | L33: =IF(K33="","",E33*K33) | M33: =IF(K33="","",IF((F33+G33)/2=0,"",K33/((F33+G33)/2)-1)) | N33: Active when Inputs toggle = 1
B34: 09 23 | C34: Veneer skim coat over drywall (plaster-look finish) | D34: SF | E34: =IF(Inputs!$C$16=1,Inputs!$C$20,0) -> 11120.518 | F34: 1.5 | G34: 3 | H34: =E34*F34 -> 16680.776 | I34: =E34*G34 -> 33361.553 | L34: =IF(K34="","",E34*K34) | M34: =IF(K34="","",IF((F34+G34)/2=0,"",K34/((F34+G34)/2)-1)) | N34: Active when Inputs toggle = 1
B35: 09 23 | C35: ALTERNATE: 3-coat plaster on lath, like-kind historic | D35: SF | E35: =IF(Inputs!$C$16=2,Inputs!$C$20,0) -> 0 | F35: 12 | G35: 25 | H35: =E35*F35 -> 0 | I35: =E35*G35 -> 0 | L35: =IF(K35="","",E35*K35) | M35: =IF(K35="","",IF((F35+G35)/2=0,"",K35/((F35+G35)/2)-1)) | N35: Active when Inputs toggle = 2 — like-kind & quality claim basis
B36: 09 91 | C36: Prime + 2 coats paint — all new wall/ceiling surfaces | D36: SF | E36: =Inputs!$C$20 -> 11120.518 | F36: 1.5 | G36: 3 | H36: =E36*F36 -> 16680.776 | I36: =E36*G36 -> 33361.553 | L36: =IF(K36="","",E36*K36) | M36: =IF(K36="","",IF((F36+G36)/2=0,"",K36/((F36+G36)/2)-1))
B37: 06 22 | C37: Remove, salvage, reinstall/replicate trim, casing, base — allowance | D37: LS | E37: 1 | F37: 4000 | G37: 9000 | H37: =E37*F37 -> 4000 | I37: =E37*G37 -> 9000 | L37: =IF(K37="","",E37*K37) | M37: =IF(K37="","",IF((F37+G37)/2=0,"",K37/((F37+G37)/2)-1)) | N37: Historic profiles; replication where damaged
B38: 08 14 | C38: Interior doors — rehang, adjust, hardware allowance | D38: LS | E38: 1 | F38: 1000 | G38: 3000 | H38: =E38*F38 -> 1000 | I38: =E38*G38 -> 3000 | L38: =IF(K38="","",E38*K38) | M38: =IF(K38="","",IF((F38+G38)/2=0,"",K38/((F38+G38)/2)-1))
B39: 09 64 | C39: Sand & refinish existing hardwood floors (2 coats poly) | D39: SF | E39: =Inputs!$C$19 -> 2438.71 | F39: 4 | G39: 8 | H39: =E39*F39 -> 9754.84 | I39: =E39*G39 -> 19509.68 | L39: =IF(K39="","",E39*K39) | M39: =IF(K39="","",IF((F39+G39)/2=0,"",K39/((F39+G39)/2)-1)) | N39: Floors mostly intact per owner; board replacement below
B40: 09 64 | C40: Hardwood board replacement allowance (cupped/stained boards) | D40: LS | E40: 1 | F40: 1500 | G40: 5000 | H40: =E40*F40 -> 1500 | I40: =E40*G40 -> 5000 | L40: =IF(K40="","",E40*K40) | M40: =IF(K40="","",IF((F40+G40)/2=0,"",K40/((F40+G40)/2)-1)) | N40: Adjust after floors dry & are inspected
B41: 01 74 | C41: Final construction clean, 3 floors | D41: SF | E41: =Inputs!$C$19 -> 2438.71 | F41: 0.5 | G41: 1 | H41: =E41*F41 -> 1219.355 | I41: =E41*G41 -> 2438.71 | L41: =IF(K41="","",E41*K41) | M41: =IF(K41="","",IF((F41+G41)/2=0,"",K41/((F41+G41)/2)-1))
C42: ARCHITECTURAL SUBTOTAL | H42: =SUM(H30:H41) -> 110096.4 | I42: =SUM(I30:I41) -> 219851.9 | L42: =SUM(L30:L41) -> 0
B44: FURNISHINGS
B45: 12 00 | C45: Contents pack-out, inventory, storage (3 months), pack-back | D45: LS | E45: 1 | F45: 3500 | G45: 9000 | H45: =E45*F45 -> 3500 | I45: =E45*G45 -> 9000 | L45: =IF(K45="","",E45*K45) | M45: =IF(K45="","",IF((F45+G45)/2=0,"",K45/((F45+G45)/2)-1)) | N45: Often paid under Contents/ALE coverage, not Dwelling
B46: 12 00 | C46: Contents cleaning/restoration allowance (soft goods, upholstery) | D46: LS | E46: 1 | F46: 1500 | G46: 5000 | H46: =E46*F46 -> 1500 | I46: =E46*G46 -> 5000 | L46: =IF(K46="","",E46*K46) | M46: =IF(K46="","",IF((F46+G46)/2=0,"",K46/((F46+G46)/2)-1)) | N46: Placeholder pending contents inventory
...

Sheet Summary
B2: Estimate Summary
B3: Historic 3-Story Residence — Attic Supply Line Failure — Detroit, MI — Ballpark for insurance discussion only; not a bid
B5: Division | C5: Low | D5: High | E5: RS Means (as entered)
B6: Mechanical | C6: =Estimate!H12 -> 11150 | D6: =Estimate!I12 -> 23700 | E6: =Estimate!L12 -> 0
B7: Electrical | C7: =Estimate!H20 -> 25034.68 | D7: =Estimate!I20 -> 45701.94 | E7: =Estimate!L20 -> 0
B8: Structural | C8: =Estimate!H27 -> 6438.71 | D8: =Estimate!I27 -> 19516.13 | E8: =Estimate!L27 -> 0
B9: Architectural | C9: =Estimate!H42 -> 110096.4 | D9: =Estimate!I42 -> 219851.9 | E9: =Estimate!L42 -> 0
B10: Furnishings | C10: =Estimate!H49 -> 5500 | D10: =Estimate!I49 -> 16000 | E10: =Estimate!L49 -> 0
B11: Direct cost subtotal | C11: =SUM(C6:C10) -> 158219.79 | D11: =SUM(D6:D10) -> 324769.97 | E11: =SUM(E6:E10) -> 0
B12: Detroit location factor adj. | C12: =C11*(Inputs!$C$13-1) -> 7910.9895 | D12: =D11*(Inputs!$C$13-1) -> 16238.498 | E12: =E11*(Inputs!$C$13-1) -> 0
B13: GC overhead & profit | C13: =(C11+C12)*Inputs!$C$14 -> 29903.54 | D13: =(D11+D12)*Inputs!$C$14 -> 61381.524 | E13: =(E11+E12)*Inputs!$C$14 -> 0
B14: Contingency | C14: =(C11+C12)*Inputs!$C$15 -> 16613.078 | D14: =(D11+D12)*Inputs!$C$15 -> 34100.847 | E14: =(E11+E12)*Inputs!$C$15 -> 0
B15: TOTAL ESTIMATE | C15: =SUM(C11:C14) -> 212647.4 | D15: =SUM(D11:D14) -> 436490.84 | E15: =SUM(E11:E14) -> 0
B17: Total floor area (SF) | C17: =Inputs!$C$19 -> 2438.71
B18: Cost per SF of floor area | C18: =IF(C17=0,"",C15/C17) -> 87.196673 | D18: =IF(C17=0,"",D15/C17) -> 178.98431
B20: Insurance notes for adjuster discussion:
B21: 1. Like-kind & quality: original finish is lath & plaster. Set Inputs toggle = 2 to price the plaster alternate the policy may owe.
B22: 2. Ordinance & Law: K&T rewire, AFCI/GFCI, insulation, and panel upgrade are code-mandated once walls open — check O&L sublimit.
B23: 3. Boiler: dry-fired cast iron can crack. Get the inspection report in writing before releasing the contingency line.
B24: 4. Contents/ALE: pack-out and furnishings usually paid under separate coverages — do not let them dilute the Dwelling limit.
B25: 5. Sources: 2026 national cost guides (HomeGuide, Angi/Homewyse, contractor pricing); validate each line against RS Means using cols J-M on the Estimate tab.

Sheet Adjuster Comparison
B2: Liberty Mutual Estimate vs. Model — Claim 061004792
B3: Adjuster direct costs from 'Recap by Category' (contractor estimate pp.30-31), mapped to divisions. Compare vs Estimate tab (which excludes location factor/O&P/contingency at line level).
B5: Division | C5: Liberty Direct $ | D5: Model Low | E5: Model High | F5: Assessment
B6: Mechanical | C6: 33721.59 | D6: =Summary!C6 -> 11150 | E6: =Summary!D6 -> 23700 | F6: COVERED WELL. HVACi boiler+radiators $30,875 RCV carried in full (line 2, w/ 20% O&P = $37,050). Plumbing rem/resets included.
B7: Electrical | C7: 837.19 | D7: =Summary!C7 -> 25034.68 | E7: =Summary!D7 -> 45701.94 | F7: MAJOR GAP. Line 3 'Bid Item, Electrical' = $0.00 open item pending city inspection. K&T rewire realistically $20-35K. Largest supplement opportunity.
B8: Structural | C8: 274.37 | D8: =Summary!C8 -> 6438.71 | E8: =Summary!D8 -> 19516.13 | F8: GAP. Only underlayment carried. No framing repair at burst location, no joist probe, NO antimicrobial/mold treatment despite loss 2/26 and inspection 6/22 (4 months wet).
B9: Architectural | C9: 111308.49 | D9: =Summary!C9 -> 110096.4 | E9: =Summary!D9 -> 219851.9 | F9: PARTIAL SCOPE. Full oak floor tear-out/replace ($46.7K — generous) but plaster is SPOT repair only (e.g. Living Rm: 66 of 625 SF walls). No lead-safe RRP containment, no insulation.
B10: Furnishings | C10: 1884.74 | D10: =Summary!C10 -> 5500 | E10: =Summary!D10 -> 16000 | F10: GAP. Only content manipulation + blinds. No pack-out/storage, no contents cleaning. Pursue under Contents coverage separately — don't dilute Dwelling.
B11: Direct cost subtotal | C11: =SUM(C6:C10) -> 148026.38 | D11: =SUM(D6:D10) -> 158219.79 | E11: =SUM(E6:E10) -> 324769.97
B13: Liberty Claim Payment Waterfall (as issued 07/10/2026)
B14: Replacement Cost Value (RCV) | C14: 179578.08 | D14: Subtotal $177,632.08 + $1,946 MI sales tax on materials
B15: Less recoverable depreciation | C15: -26641.23 | D15: 50% dep on materials only — RECOVERABLE on completion of repairs
B16: Net ACV on Coverage Building | C16: 152936.85
B17: Less deductible | C17: -5000
B18: Net estimate (check today) | C18: 147936.85
B19: Net if depreciation recovered | C19: 174578.08 | D19: Submit completion invoices to recover the $26,641
B20: Coverage A limit | C20: 776800 | D20: Ample headroom for supplements — limit is NOT the constraint
B22: Supplement Strategy — priority order
B23: 1. ELECTRICAL ($0 open item): Get the City of Detroit electrical inspection scheduled NOW. Walls will be open — the K&T rewire supplement ($20-35K) hinges on that inspection report. Line 3 of the estimate explicitly leaves the door open.
B24: 2. MOLD/ANTIMICROBIAL: 4 months elapsed between loss and inspection. Have an industrial hygienist or IICRC remediation firm document cavity conditions during demo. Supplement immediately if found — resulting mold from a covered water loss is typically covered (check sublimit).
B25: 3. PLASTER SCOPE: Liberty scoped spot plaster repair (~2,000 of 11,112 SF surface). If demo reveals plaster keys sheared/delaminated beyond scoped areas, document per-room with photos and supplement. Their own line items ($6.82-7.80/SF, 3-coat) become the agreed unit price — good pricing to extend.
B26: 4. LEAD-SAFE RRP: Pre-1978 home; EPA RRP containment is legally required for the contractor and is a compensable cost not in the estimate (~$0.50-1.50/SF disturbed).
B27: 5. PERMITS ($0 open item, line 4): Submit actual permit receipts as incurred.
B28: 6. DEPRECIATION RECOVERY: $26,641 is recoverable — keep every invoice, submit at completion.
B29: 7. CONTENTS/ALE: Pack-out, storage, contents cleaning are absent. File under Coverage C (Contents) and ALE if the house is uninhabitable — separate limits from the $776,800 Dwelling.
