Workbook

Sheet Takeoff
B2: Quantity Takeoff — from Liberty Mutual Xactimate Sketches (Claim 061004792)
B3: Source: 'Floorplan' recap pages 25-27 of contractor estimate, sketches dated 07/10/2026. 8'-0" flat ceilings throughout per room headers.
B5: Floor (sketch name) | C5: Walls SF | D5: Walls+Ceilings SF | E5: Floors SF | F5: Floor Perim LF | G5: Ceilings SF | H5: Ceiling Perim LF
B6: 1st floor | C6: 3331.28 | D6: 4272.1 | E6: 940.7 | F6: 297.99 | G6: 940.82 | H6: 406.27
B7: 2nd floor 2 | C7: 3576.6 | D7: 4532.97 | E7: 956.28 | F7: 328.28 | G7: 956.37 | H7: 447.15
B8: 3rd floor 2 | C8: 1765.3 | D8: 2307.03 | E8: 541.73 | F8: 155.59 | G8: 541.73 | H8: 212.03
B9: B1 2 (bsmt) | C9: 2525.29 | D9: 3471.38 | E9: 946.09 | F9: 205.97 | G9: 946.09 | H9: 315.71
B10: TOTAL (incl basement) | C10: =SUM(C6:C9) -> 11198.47 | D10: =SUM(D6:D9) -> 14583.48 | E10: =SUM(E6:E9) -> 3384.8 | F10: =SUM(F6:F9) -> 987.83 | G10: =SUM(G6:G9) -> 3385.01 | H10: =SUM(H6:H9) -> 1381.16
B11: TOTAL above grade | C11: =SUM(C6:C8) -> 8673.18 | D11: =SUM(D6:D8) -> 11112.1 | E11: =SUM(E6:E8) -> 2438.71 | F11: =SUM(F6:F8) -> 781.86 | G11: =SUM(G6:G8) -> 2438.92 | H11: =SUM(H6:H8) -> 1065.45
B13: Derived / assumption-driven quantities (yellow = confirm in field)
B14: Quantity | C14: Value | D14: Unit | E14: Basis / Question ref
B15: Wall+ceiling surface, above grade | C15: =D11 -> 11112.1 | D15: SF | E15: Actual takeoff
B16: Plaster replacement scope factor | C16: 0.85 | D16: x | E16: Q-A3: % of surface actually failed — Liberty scoped ~18%; owner premise is ~100%; set after demo
B17: Plaster surface to replace | C17: =C15*C16 -> 9445.285 | D17: SF | E17: surface x scope factor
B18: Electrical openings (count in field) | C18: 95 | D18: EA | E18: Q-E4: placeholder = 2.5/100 SF floor + code adds; COUNT ACTUAL
B19: Radiator count | C19: 12 | D19: EA | E19: Q-M3: HVACi carried 'radiator replacement' LS — count units, note EDR sizes
B20: Interior door count | C20: 18 | D20: EA | E20: Q-A9: count; note stain vs paint grade
B21: Trim: base/base shoe | C21: =F11 -> 781.86 | D21: LF | E21: Floor perimeter proxy; confirm profile stack (Q-A7)
B22: Trim: crown | C22: =H11 -> 1065.45 | D22: LF | E22: Ceiling perimeter proxy; not all rooms have crown (Q-A7)
B23: Oak flooring | C23: 2160.05 | D23: SF | E23: Liberty carried 2,160 SF tear-out+replace incl 10% waste — validate

Sheet Means Grid
B2: RS Means Pricing Grid — with Low/High Planning Values
B3: Est Low/High are 2026 planning unit costs (installed, national) for orientation BEFORE the Means lookup. Fill cols J-P from RS Means; CCI applies to Means path only. Gray ALT rows = drywall alternate, excluded from totals.
B4: Detroit CCI (confirm — Q-G5): | F4: 1.05
B6: CSI Section | C6: Line Item | D6: Unit | E6: Qty | F6: Est $/u Low | G6: Est $/u High | H6: Ext $ Low | I6: Ext $ High | J6: Means Line # | K6: Crew | L6: Daily Output | M6: Bare Mat | N6: Bare Labor | O6: Bare Equip | P6: Incl O&P $/u | Q6: CCI-Adj $/u | R6: Means Ext $ | S6: Notes
B7: GENERAL CONDITIONS & DEMOLITION
B8: 01 54 23 | C8: Temporary scaffolding/ladders, stair & 3rd-floor work | D8: MO | E8: 3 | F8: 800 | G8: 2000 | H8: =E8*F8 -> 2400 | I8: =E8*G8 -> 6000 | Q8: =IF(P8="","",P8*'Means Grid'!$F$4) | R8: =IF(Q8="","",Q8*E8) | S8: Duration from Q-G3 schedule
B9: 02 41 19 | C9: Selective demo — plaster & lath, walls/ceilings | D9: SF | E9: =Takeoff!$C$17 -> 9445.285 | F9: 2 | G9: 4 | H9: =E9*F9 -> 18890.57 | I9: =E9*G9 -> 37781.14 | Q9: =IF(P9="","",P9*'Means Grid'!$F$4) | R9: =IF(Q9="","",Q9*E9) | S9: Gut wall/ceiling plaster incl lath
B10: 02 41 19 | C10: Debris hauling & disposal, dumpsters | D10: EA | E10: 8 | F10: 450 | G10: 700 | H10: =E10*F10 -> 3600 | I10: =E10*G10 -> 5600 | Q10: =IF(P10="","",P10*'Means Grid'!$F$4) | R10: =IF(Q10="","",Q10*E10) | S10: Q-G2 — Liberty carried ONE 10-yd
B11: 02 83 19 | C11: Lead-safe containment (RRP) premium | D11: SF | E11: =Takeoff!$C$17 -> 9445.285 | F11: 0.5 | G11: 1.5 | H11: =E11*F11 -> 4722.6425 | I11: =E11*G11 -> 14167.927 | Q11: =IF(P11="","",P11*'Means Grid'!$F$4) | R11: =IF(Q11="","",Q11*E11) | S11: Pre-1978; Q-S4 XRF sets scope
B12: 02 26 23 | C12: Asbestos survey + abatement allowance | D12: LS | E12: 1 | F12: 800 | G12: 8000 | H12: =E12*F12 -> 800 | I12: =E12*G12 -> 8000 | Q12: =IF(P12="","",P12*'Means Grid'!$F$4) | R12: =IF(Q12="","",Q12*E12) | S12: Q-S3 — high end if lagging positive
B13: 02 87 13 | C13: Antimicrobial treatment, exposed cavities | D13: SF | E13: =Takeoff!$E$11 -> 2438.71 | F13: 1 | G13: 3 | H13: =E13*F13 -> 2438.71 | I13: =E13*G13 -> 7316.13 | Q13: =IF(P13="","",P13*'Means Grid'!$F$4) | R13: =IF(Q13="","",Q13*E13) | S13: Q-S2 hygienist sets actual SF
B14: STRUCTURAL / ROUGH CARPENTRY
B15: 06 11 10 | C15: Joist sistering allowance, saturated members | D15: EA | E15: 10 | F15: 150 | G15: 400 | H15: =E15*F15 -> 1500 | I15: =E15*G15 -> 4000 | Q15: =IF(P15="","",P15*'Means Grid'!$F$4) | R15: =IF(Q15="","",Q15*E15) | S15: Q-S1 probe count after demo
B16: 06 11 10 | C16: Attic framing/sheathing repair at burst | D16: SF | E16: 100 | F16: 8 | G16: 20 | H16: =E16*F16 -> 800 | I16: =E16*G16 -> 2000 | Q16: =IF(P16="","",P16*'Means Grid'!$F$4) | R16: =IF(Q16="","",Q16*E16) | S16: Q-S1 measure damaged area
B17: 06 16 23 | C17: Subfloor/underlayment repair | D17: SF | E17: 300 | F17: 3 | G17: 7 | H17: =E17*F17 -> 900 | I17: =E17*G17 -> 2100 | Q17: =IF(P17="","",P17*'Means Grid'!$F$4) | R17: =IF(Q17="","",Q17*E17) | S17: Beyond Liberty's felt-only line
B18: MECHANICAL (Div 22/23)
B19: 23 52 33 | C19: Cast-iron gas boiler, ~210 MBH, installed | D19: EA | E19: 1 | F19: 9000 | G19: 14000 | H19: =E19*F19 -> 9000 | I19: =E19*G19 -> 14000 | Q19: =IF(P19="","",P19*'Means Grid'!$F$4) | R19: =IF(Q19="","",Q19*E19) | S19: HVACi carried $8,429 boiler line — low
B20: 23 82 29 | C20: Cast-iron radiator, remove & replace | D20: EA | E20: =Takeoff!$C$19 -> 12 | F20: 900 | G20: 1800 | H20: =E20*F20 -> 10800 | I20: =E20*G20 -> 21600 | Q20: =IF(P20="","",P20*'Means Grid'!$F$4) | R20: =IF(Q20="","",Q20*E20) | S20: HVACi: $15,472 LS all units (~$1,290/EA @12)
B21: 23 21 13 | C21: Hydronic piping repairs/reconnection | D21: LS | E21: 1 | F21: 1500 | G21: 4000 | H21: =E21*F21 -> 1500 | I21: =E21*G21 -> 4000 | Q21: =IF(P21="","",P21*'Means Grid'!$F$4) | R21: =IF(Q21="","",Q21*E21) | S21: Q-M2 pipe material/condition
B22: 22 11 16 | C22: Domestic supply line repair at attic + valves | D22: LS | E22: 1 | F22: 1500 | G22: 3500 | H22: =E22*F22 -> 1500 | I22: =E22*G22 -> 3500 | Q22: =IF(P22="","",P22*'Means Grid'!$F$4) | R22: =IF(Q22="","",Q22*E22) | S22: Cause of loss
B23: 22 07 19 | C23: Pipe insulation, attic runs | D23: LF | E23: 60 | F23: 8 | G23: 15 | H23: =E23*F23 -> 480 | I23: =E23*G23 -> 900 | Q23: =IF(P23="","",P23*'Means Grid'!$F$4) | R23: =IF(Q23="","",Q23*E23) | S23: Q-M4 measure runs
B24: ELECTRICAL (Div 26)
B25: 26 05 19 | C25: K&T rewire — branch circuits, walls open | D25: SF | E25: =Takeoff!$E$10 -> 3384.8 | F25: 8 | G25: 14 | H25: =E25*F25 -> 27078.4 | I25: =E25*G25 -> 47387.2 | Q25: =IF(P25="","",P25*'Means Grid'!$F$4) | R25: =IF(Q25="","",Q25*E25) | S25: Q-E1: basis incl basement; open walls = low end
B26: 26 24 16 | C26: Panelboard 200A + service upgrade | D26: EA | E26: 1 | F26: 2500 | G26: 4500 | H26: =E26*F26 -> 2500 | I26: =E26*G26 -> 4500 | Q26: =IF(P26="","",P26*'Means Grid'!$F$4) | R26: =IF(Q26="","",Q26*E26) | S26: Q-E2 service size/location
B27: 26 27 26 | C27: Devices & plates (period style premium) | D27: EA | E27: =Takeoff!$C$18 -> 95 | F27: 25 | G27: 60 | H27: =E27*F27 -> 2375 | I27: =E27*G27 -> 5700 | Q27: =IF(P27="","",P27*'Means Grid'!$F$4) | R27: =IF(Q27="","",Q27*E27) | S27: Q-E4 count; Q-E5 style
B28: 26 51 13 | C28: Light fixtures, rem/reset or replace | D28: EA | E28: 12 | F28: 100 | G28: 250 | H28: =E28*F28 -> 1200 | I28: =E28*G28 -> 3000 | Q28: =IF(P28="","",P28*'Means Grid'!$F$4) | R28: =IF(Q28="","",Q28*E28) | S28: Count (Q-E4)
B29: 28 46 21 | C29: Smoke/CO interconnected, code | D29: EA | E29: 8 | F29: 100 | G29: 200 | H29: =E29*F29 -> 800 | I29: =E29*G29 -> 1600 | Q29: =IF(P29="","",P29*'Means Grid'!$F$4) | R29: =IF(Q29="","",Q29*E29) | S29: MI code, per floor + bedrooms
B30: ARCHITECTURAL FINISHES (Div 06/08/09)
B31: 09 22 36 | C31: Wood/metal lath, new | D31: SF | E31: =Takeoff!$C$17 -> 9445.285 | F31: 3.5 | G31: 5.5 | H31: =E31*F31 -> 33058.497 | I31: =E31*G31 -> 51949.067 | Q31: =IF(P31="","",P31*'Means Grid'!$F$4) | R31: =IF(Q31="","",Q31*E31) | S31: Q-A2 lath type; Liberty $3.69-4.07
B32: 09 23 20 | C32: Gypsum plaster, 3-coat on lath, walls & clgs | D32: SF | E32: =Takeoff!$C$17 -> 9445.285 | F32: 7 | G32: 14 | H32: =E32*F32 -> 66116.995 | I32: =E32*G32 -> 132233.99 | Q32: =IF(P32="","",P32*'Means Grid'!$F$4) | R32: =IF(Q32="","",Q32*E32) | S32: Liberty $6.82-7.80 = below market
B33: 09 29 10 | C33: ALT: 1/2" drywall hung/taped/finished L4 | D33: SF | E33: =Takeoff!$C$17 -> 9445.285 | F33: 2.5 | G33: 4 | H33: =E33*F33 -> 23613.213 | I33: =E33*G33 -> 37781.14 | Q33: =IF(P33="","",P33*'Means Grid'!$F$4) | R33: =IF(Q33="","",Q33*E33) | S33: Alternate path — excluded from totals
B34: 09 23 20 | C34: ALT: veneer skim over drywall | D34: SF | E34: =Takeoff!$C$17 -> 9445.285 | F34: 1.5 | G34: 3 | H34: =E34*F34 -> 14167.927 | I34: =E34*G34 -> 28335.855 | Q34: =IF(P34="","",P34*'Means Grid'!$F$4) | R34: =IF(Q34="","",Q34*E34) | S34: Pairs with drywall ALT — excluded
B35: 09 91 23 | C35: Prime + 2 coats, walls & ceilings | D35: SF | E35: =Takeoff!$C$15 -> 11112.1 | F35: 1.5 | G35: 3 | H35: =E35*F35 -> 16668.15 | I35: =E35*G35 -> 33336.3 | Q35: =IF(P35="","",P35*'Means Grid'!$F$4) | R35: =IF(Q35="","",Q35*E35) | S35: Full repaint; Liberty $1.37-1.52
B36: 06 22 13 | C36: Base/shoe/casing rem-reset & refinish | D36: LF | E36: =Takeoff!$C$21 -> 781.86 | F36: 6 | G36: 12 | H36: =E36*F36 -> 4691.16 | I36: =E36*G36 -> 9382.32 | Q36: =IF(P36="","",P36*'Means Grid'!$F$4) | R36: =IF(Q36="","",Q36*E36) | S36: Q-A7 profiles; stain vs paint grade
B37: 06 22 13 | C37: Crown molding rem-reset & refinish | D37: LF | E37: =Takeoff!$C$22 -> 1065.45 | F37: 6 | G37: 12 | H37: =E37*F37 -> 6392.7 | I37: =E37*G37 -> 12785.4 | Q37: =IF(P37="","",P37*'Means Grid'!$F$4) | R37: =IF(Q37="","",Q37*E37) | S37: Q-A7 which rooms have crown
B38: 08 14 33 | C38: Interior doors — rem/reset, refinish, replace mix | D38: EA | E38: =Takeoff!$C$20 -> 18 | F38: 150 | G38: 600 | H38: =E38*F38 -> 2700 | I38: =E38*G38 -> 10800 | Q38: =IF(P38="","",P38*'Means Grid'!$F$4) | R38: =IF(Q38="","",Q38*E38) | S38: Q-A9 replace vs refinish mix
B39: 09 64 29 | C39: Oak strip flooring 2-1/4" #1 common, R&R | D39: SF | E39: =Takeoff!$C$23 -> 2160.05 | F39: 12 | G39: 18 | H39: =E39*F39 -> 25920.6 | I39: =E39*G39 -> 38880.9 | Q39: =IF(P39="","",P39*'Means Grid'!$F$4) | R39: =IF(Q39="","",Q39*E39) | S39: Liberty $12.06 + $2.08 diagonal ≈ $14.14
B40: 09 64 29 | C40: Sand, stain, 2-ct poly, dustless | D40: SF | E40: =Takeoff!$C$23 -> 2160.05 | F40: 4 | G40: 8 | H40: =E40*F40 -> 8640.2 | I40: =E40*G40 -> 17280.4 | Q40: =IF(P40="","",P40*'Means Grid'!$F$4) | R40: =IF(Q40="","",Q40*E40) | S40: Liberty $9.21 — above typical, keep it
B41: 09 30 13 | C41: Ceramic tile walls, bathroom R&R + cement bd | D41: SF | E41: 280 | F41: 18 | G41: 30 | H41: =E41*F41 -> 5040 | I41: =E41*G41 -> 8400 | Q41: =IF(P41="","",P41*'Means Grid'!$F$4) | R41: =IF(Q41="","",Q41*E41) | S41: Liberty $15.61 tile + $4.72 board ≈ $20.33
B42: 12 32 16 | C42: Kitchen/pantry cabinetry & counters R&R | D42: LS | E42: 1 | F42: 5000 | G42: 9000 | H42: =E42*F42 -> 5000 | I42: =E42*G42 -> 9000 | Q42: =IF(P42="","",P42*'Means Grid'!$F$4) | R42: =IF(Q42="","",Q42*E42) | S42: Liberty ~$5.9K; verify LF Q-A10
...

Sheet Questions
B2: Field Questions — with Dollar Swing
B3: Swing Low/High = how much the answer can move the claim (direct cost). Sort your field time by the Swing High column. Orange = >$10K potential.
B5: ID | C5: Question | D5: Why it matters / feeds | E5: Swing $ Low | F5: Swing $ High | G5: Answer
B6: GENERAL & PROJECT CONDITIONS
B7: Q-G1 | C7: Occupied during repairs, or vacant? ALE claim active? | D7: Occupied-building factors; phasing/protection cost | E7: 0 | F7: 8000
B8: Q-G2 | C8: Site logistics: dumpster placement, street permit, staging, alley access? | D8: Liberty carried ONE 10-yd dumpster; full demo needs 6-10 + possible street occupancy permit | E8: 2500 | F8: 6000
B9: Q-G3 | C9: Schedule/phasing? Winter work with boiler dead = temporary heat? | D9: Temp heat $1.5-3K/winter month; scaffolding duration | E9: 0 | F9: 9000
B10: Q-G4 | C10: GC vs self-perform? Union or open shop? | D10: Detroit union vs open-shop labor spread 20-40% on ~$100K labor | E10: 0 | F10: 30000
B11: Q-G5 | C11: Current RS Means Detroit CCI (2026, residential)? | D11: Multiplier on entire Means comparison (±5% ≈ ±$10K) | E11: -10000 | F11: 10000
B12: Q-G6 | C12: Virginia Park historic district review required? | D12: HDC can MANDATE like-kind plaster → converts drywall scope to plaster scope | E12: 0 | F12: 60000
B13: STRUCTURAL & ENVIRONMENTAL
B14: Q-S1 | C14: Post-demo: joists/studs rotted or crushed? Attic sheathing damage SF? | D14: Sistering EA + sheathing SF — currently pure allowance | E14: 1000 | F14: 12000
B15: Q-S2 | C15: Hygienist/IICRC: visible mold in cavities? Affected SF? Moisture map? | D15: 4 months wet. Remediation + retesting; check mold sublimit | E15: 0 | F15: 25000
B16: Q-S3 | C16: Asbestos: plaster + boiler pipe lagging tested? | D16: Positive lagging = licensed abatement before ANY boiler work | E16: 800 | F16: 12000
B17: Q-S4 | C17: Lead XRF: which surfaces positive? | D17: RRP containment SF; fines for non-compliance are contractor's problem but cost is claimable | E17: 4000 | F17: 15000
B18: MECHANICAL
B19: Q-M1 | C19: Boiler venting: chimney liner condition? Gas line sized for 210 MBH? | D19: Liner $2-4K not in HVACi quote | E19: 0 | F19: 4000
B20: Q-M2 | C20: Distribution piping steel or copper? Splits beyond radiators? | D20: Hidden riser splits = open scope inside walls | E20: 0 | F20: 8000
B21: Q-M3 | C21: Radiator count + EDR; how many actually cracked? | D21: HVACi carried ALL at $15,472 — salvageable units cut cost; more units raise it | E21: -5000 | F21: 6000
B22: Q-M4 | C22: LF of attic/exterior-wall pipe needing insulation? | D22: Freeze prevention | E22: 300 | F22: 1200
B23: Q-M5 | C23: Water heater / domestic side affected? | D23: Scope boundary | E23: 0 | F23: 2500
B24: ELECTRICAL
B25: Q-E1 | C25: K&T extent: whole house? Which circuits live? Basement included? | D25: THE $0 open item. Rewire basis 2,439-3,385 SF @ $8-14 | E25: 20000 | F25: 47000
B26: Q-E2 | C26: Service amperage, panel type, fuse box? Service drop condition? | D26: 200A upgrade + DTE service work | E26: 2500 | F26: 6500
B27: Q-E3 | C27: City of Detroit inspection scheduled? Written scope? | D27: The supplement document — no inspection, no supplement | E27: 0 | F27: 0
B28: Q-E4 | C28: Actual opening count per floor (walk & count) | D28: 95 EA placeholder; NEC 12-ft rule adds receptacles | E28: 2000 | F28: 6000
B29: Q-E5 | C29: Period push-button devices / brass plates, or standard? | D29: $25-60/opening premium ×~95 | E29: 2400 | F29: 5700
B30: Q-E6 | C30: K&T in insulation-contact areas (attic floor)? | D30: Code prohibition; sequencing with insulation | E30: 0 | F30: 1500
B31: ARCHITECTURAL
B32: Q-A1 | C32: Room-by-room tap test: which plaster is DELAMINATED vs paint-damaged? Photos per room. | D32: THE scope question. Liberty ~2,000 SF vs potential 9,400+ SF @ ~$12-19/SF full system (lath+plaster+paint) | E32: 30000 | F32: 160000
B33: Q-A2 | C33: Lath type: wood, metal, rock lath? Plaster thickness? | D33: Means line selection; wood lath = premium | E33: 0 | F33: 15000
B34: Q-A3 | C34: Ceiling heights really 8'-0" on floor 1? (1920s houses often 9') | D34: 9' actual = Liberty wall SF understated ~12% on floor 1 (~500 SF surface) | E34: 0 | F34: 8000
B35: Q-A4 | C35: Ornamental plaster: crown runs, medallions, arches, coves? | D35: Specialty pricing 5-10x flat work if present | E35: 0 | F35: 20000
B36: Q-A5 | C36: Confirm 2-1/4" #1 common oak, diagonal install, felt underlayment | D36: Diagonal add-on ~$2/SF ×2,160 already carried — protect it | E36: 0 | F36: 4500
B37: Q-A6 | C37: Floor 3: painted softwood or oak? (Liberty primed & painted it) | D37: Painted fir vs oak R&R = entirely different line | E37: 0 | F37: 6000
B38: Q-A7 | C38: Trim inventory per room: profile stack, stain vs paint grade, crown locations | D38: Stain-grade refinish ≈ 2x paint-grade cost | E38: 3000 | F38: 12000
B39: Q-A8 | C39: Bathroom tile SF + bullnose; 3rd floor bath scoped correctly? | D39: 3rd flr bath NOT tiled in Liberty scope — verify field condition | E39: 0 | F39: 8000
B40: Q-A9 | C40: Door schedule: count, type, refinish vs replace (humidity warping) | D40: Replace $600-1,200/EA vs refinish $150 | E40: 2000 | F40: 9000
B41: Q-A10 | C41: Kitchen cabinet LF, counter material, appliances affected? | D41: Liberty ~$5.9K; undersized if uppers/appliances hit | E41: 0 | F41: 7000
B42: Q-A11 | C42: Wall cavity insulation existing? Attic R-value? Add while open? | D42: O&L code-upgrade candidate; $1.50-3.50/SF while open | E42: 3500 | F42: 8500
...

Sheet Reference
B2: RS Means Assessment Conventions
B4: BOOK: Use RS Means Residential Repair & Remodeling Cost Data 2026 for most lines (repair/remodel productivity, small-job factors). Use Building Construction Cost Data (BCCD) for the boiler and service upgrade.
B5: LOCATION: Apply Detroit City Cost Index (CCI) — enter the current published figure in Means Grid F4. Note Means CCI ≠ Xactimate Cotality pricing basis; expect 5-15% structural divergence between the two databases even on identical scope.
B6: O&P: Means 'Total Incl O&P' includes installing-contractor O&P only. Add GC markup (10+10 like Liberty, or your 18%) on top when comparing to the claim RCV. Liberty's RCV = direct + 6% MI tax on materials + 10% OH + 10% profit.
B7: SMALL JOB FACTORS: Repair/remodel work in an occupied historic house warrants Means minimum-labor and cut & patch factors — do not price from new-construction productivity.
B8: COMPARISON BASIS: Liberty pricing DB = 'Cotality Data Driven USDC — February 2026 (Michigan)(Detroit)'. When disputing a unit price, cite the Means line number + CCI; adjusters respond to sourced numbers.
B9: PLASTER STRATEGY: Liberty's own carried unit prices (3-coat plaster $6.82/SF walls, $7.80/SF ceilings, lath $3.69-4.07/SF) are BELOW typical Means 3-coat-on-wood-lath pricing. If Means comes in higher, that supports extending THEIR unit price to a LARGER scope rather than fighting the rate — the scope (Q-A1) is where the money is.
B10: KEY DOC FACTS: Claim 061004792 · Policy OX6720664 (American Economy Ins. Co.) · Deductible $5,000 · Coverage A $776,800 · DOL 02/26/2026 · RCV $179,578.08 · ACV $152,936.85 · Net paid $147,936.85 · Recoverable dep $26,641.23 · Adjuster: Rosanne Henrichs (509) 944-8694 · Estimator: JC Windmueller.
